<?xml version="1.0" encoding="utf-8"?>
<!-- This URDF was automatically created by SolidWorks to URDF Exporter! Originally created by Stephen Brawner (brawner@gmail.com) 
     Commit Version: 1.6.0-1-g15f4949  Build Version: 1.6.7594.29634
     For more information, please see http://wiki.ros.org/sw_urdf_exporter -->
<robot
  name="CLAB_BASE_ORIENTED_URDF">
  <link
    name="base_link">
    <inertial>
      <origin
        xyz="-8.50437310875233E-11 0.0159813714834693 0.00250000000000011"
        rpy="0 0 0" />
      <mass
        value="3.31941677205457" />
      <inertia
        ixx="0.0283956856483239"
        ixy="1.56957942991156E-11"
        ixz="-1.86103072158852E-19"
        iyy="0.0404453893416239"
        iyz="1.14035651031417E-17"
        izz="0.0688272440867309" />
    </inertial>
    <visual>
      <origin
        xyz="0 0 0"
        rpy="0 0 0" />
      <geometry>
        <mesh
          filename="package://clab_base_oriented_urdf/meshes/base_link.STL" />
      </geometry>
      <material
        name="">
        <color
          rgba="0.647058823529412 0.619607843137255 0.588235294117647 1" />
      </material>
    </visual>
    <collision>
      <origin
        xyz="0 0 0"
        rpy="0 0 0" />
      <geometry>
        <mesh
          filename="package://clab_base_oriented_urdf/meshes/base_link.STL" />
      </geometry>
    </collision>
  </link>
  <link
    name="wheel_right">
    <inertial>
      <origin
        xyz="0.00491241527948272 -6.9730174409588E-07 0.0071224127649539"
        rpy="0 0 0" />
      <mass
        value="0.684010339144008" />
      <inertia
        ixx="0.00182152617330921"
        ixy="4.07158064480081E-09"
        ixz="-3.25164912110965E-07"
        iyy="0.0010059719322362"
        iyz="7.59548912912029E-09"
        izz="0.000987737299333639" />
    </inertial>
    <visual>
      <origin
        xyz="0 0 0"
        rpy="0 0 0" />
      <geometry>
        <mesh
          filename="package://clab_base_oriented_urdf/meshes/wheel_right.STL" />
      </geometry>
      <material
        name="">
        <color
          rgba="0.792156862745098 0.819607843137255 0.933333333333333 1" />
      </material>
    </visual>
    <collision>
      <origin
        xyz="0 0 0"
        rpy="0 0 0" />
      <geometry>
        <mesh
          filename="package://clab_base_oriented_urdf/meshes/wheel_right.STL" />
      </geometry>
    </collision>
  </link>
  <joint
    name="wheel_rightjoint"
    type="continuous">
    <origin
      xyz="-0.1259 -0.076925 0.00895"
      rpy="0 0 0" />
    <parent
      link="base_link" />
    <child
      link="wheel_right" />
    <axis
      xyz="-1 0 0" />
    <limit
      effort="100"
      velocity="100" />
  </joint>
  <link
    name="wheel_left">
    <inertial>
      <origin
        xyz="-0.00491241527948273 6.97301744387313E-07 0.00712241276495473"
        rpy="0 0 0" />
      <mass
        value="0.684010339144008" />
      <inertia
        ixx="0.00182152617330921"
        ixy="4.07158064394683E-09"
        ixz="3.25164912109636E-07"
        iyy="0.0010059719322362"
        iyz="-7.59548912912119E-09"
        izz="0.000987737299333639" />
    </inertial>
    <visual>
      <origin
        xyz="0 0 0"
        rpy="0 0 0" />
      <geometry>
        <mesh
          filename="package://clab_base_oriented_urdf/meshes/wheel_left.STL" />
      </geometry>
      <material
        name="">
        <color
          rgba="0.792156862745098 0.819607843137255 0.933333333333333 1" />
      </material>
    </visual>
    <collision>
      <origin
        xyz="0 0 0"
        rpy="0 0 0" />
      <geometry>
        <mesh
          filename="package://clab_base_oriented_urdf/meshes/wheel_left.STL" />
      </geometry>
    </collision>
  </link>
  <joint
    name="wheel_leftjoint"
    type="continuous">
    <origin
      xyz="0.1259 -0.076925 0.00895"
      rpy="0 0 0" />
    <parent
      link="base_link" />
    <child
      link="wheel_left" />
    <axis
      xyz="1 0 0" />
    <limit
      effort="100"
      velocity="100" />
  </joint>
  <link
    name="caster_swivel">
    <inertial>
      <origin
        xyz="0.00096547437118144 0.026637559605482 -0.0346140664152665"
        rpy="0 0 0" />
      <mass
        value="0.134113257655034" />
      <inertia
        ixx="6.4323152854494E-05"
        ixy="-4.0209734662828E-07"
        ixz="1.1649817914467E-07"
        iyy="5.31303131099225E-05"
        iyz="3.26692719885787E-06"
        izz="5.60240583999466E-05" />
    </inertial>
    <visual>
      <origin
        xyz="0 0 0"
        rpy="0 0 0" />
      <geometry>
        <mesh
          filename="package://clab_base_oriented_urdf/meshes/caster_swivel.STL" />
      </geometry>
      <material
        name="">
        <color
          rgba="0.792156862745098 0.819607843137255 0.933333333333333 1" />
      </material>
    </visual>
    <collision>
      <origin
        xyz="0 0 0"
        rpy="0 0 0" />
      <geometry>
        <mesh
          filename="package://clab_base_oriented_urdf/meshes/caster_swivel.STL" />
      </geometry>
    </collision>
  </link>
  <joint
    name="swivel_joint"
    type="revolute">
    <origin
      xyz="0 0.1225 0"
      rpy="0 0 0" />
    <parent
      link="base_link" />
    <child
      link="caster_swivel" />
    <axis
      xyz="0 0 -1" />
    <limit
      lower="0"
      upper="0"
      effort="0"
      velocity="0" />
  </joint>
  <link
    name="caster_wheel">
    <inertial>
      <origin
        xyz="3.68628738645072E-18 0 0"
        rpy="0 0 0" />
      <mass
        value="0.0662597925360328" />
      <inertia
        ixx="4.21221240717744E-05"
        ixy="-5.55945116336051E-07"
        ixz="-1.24770238492056E-18"
        iyy="2.66215023572609E-05"
        iyz="4.42628331961545E-20"
        izz="2.66015884200546E-05" />
    </inertial>
    <visual>
      <origin
        xyz="0 0 0"
        rpy="0 0 0" />
      <geometry>
        <mesh
          filename="package://clab_base_oriented_urdf/meshes/caster_wheel.STL" />
      </geometry>
      <material
        name="">
        <color
          rgba="0.792156862745098 0.819607843137255 0.933333333333333 1" />
      </material>
    </visual>
    <collision>
      <origin
        xyz="0 0 0"
        rpy="0 0 0" />
      <geometry>
        <mesh
          filename="package://clab_base_oriented_urdf/meshes/caster_wheel.STL" />
      </geometry>
    </collision>
  </link>
  <joint
    name="caster_whl_jnt"
    type="continuous">
    <origin
      xyz="0.001212 0.15354 -0.042461"
      rpy="0 0 0" />
    <parent
      link="base_link" />
    <child
      link="caster_wheel" />
    <axis
      xyz="-0.99936 0.035797 0" />
    <limit
      effort="100"
      velocity="100" />
  </joint>
  <link
    name="laser_link">
    <inertial>
      <origin
        xyz="0.000215981363826668 0.0430266372519361 -0.0380351658134059"
        rpy="0 0 0" />
      <mass
        value="0.21426881735577" />
      <inertia
        ixx="0.000240494558642832"
        ixy="-6.17113925619745E-08"
        ixz="6.11467207181745E-08"
        iyy="0.000193858915028837"
        iyz="-2.88063997450774E-05"
        izz="0.000300766562794737" />
    </inertial>
    <visual>
      <origin
        xyz="0 0 0"
        rpy="0 0 0" />
      <geometry>
        <mesh
          filename="package://clab_base_oriented_urdf/meshes/laser_link.STL" />
      </geometry>
      <material
        name="">
        <color
          rgba="0.792156862745098 0.819607843137255 0.933333333333333 1" />
      </material>
    </visual>
    <collision>
      <origin
        xyz="0 0 0"
        rpy="0 0 0" />
      <geometry>
        <mesh
          filename="package://clab_base_oriented_urdf/meshes/laser_link.STL" />
      </geometry>
    </collision>
  </link>
  <joint
    name="laser_joint"
    type="fixed">
    <origin
      xyz="0.00057241 -0.15541 0.088932"
      rpy="0 0 0" />
    <parent
      link="base_link" />
    <child
      link="laser_link" />
    <axis
      xyz="0 0 1" />
  </joint>
</robot>